2022-01-01 17:55:24,280 - instabot version: 0.117.0 (bot) - INFO - Instabot version: 0.117.0 Started
2022-01-01 17:55:24,280 - instabot version: 0.117.0 (bot) - DEBUG - Bot imported from C:\Users\tkhab\PycharmProjects\InstagramSubMonitoring\venv\lib\site-packages\instabot\bot\bot.py
2022-01-01 17:55:24,281 - instabot version: 0.117.0 (api_login) - INFO - Not yet logged in starting: PRE-LOGIN FLOW!
2022-01-01 17:55:36,289 - instabot version: 0.117.0 (api) - WARNING - HTTPSConnectionPool(host='i.instagram.com', port=443): Max retries exceeded with url: /api/v1/accounts/get_prefill_candidates/ (Caused by NewConnectionError('<urllib3.connection.HTTPSConnection object at 0x000002AF758880A0>: Failed to establish a new connection: [Errno 11001] getaddrinfo failed'))
2022-01-01 17:55:48,300 - instabot version: 0.117.0 (api) - WARNING - HTTPSConnectionPool(host='i.instagram.com', port=443): Max retries exceeded with url: /api/v1/qe/sync/ (Caused by NewConnectionError('<urllib3.connection.HTTPSConnection object at 0x000002AF758880D0>: Failed to establish a new connection: [Errno 11001] getaddrinfo failed'))
2022-01-01 17:56:00,307 - instabot version: 0.117.0 (api) - WARNING - HTTPSConnectionPool(host='i.instagram.com', port=443): Max retries exceeded with url: /api/v1/launcher/sync/ (Caused by NewConnectionError('<urllib3.connection.HTTPSConnection object at 0x000002AF75888040>: Failed to establish a new connection: [Errno 11001] getaddrinfo failed'))
